<?xml version="1.0"?>
<robot xmlns:xacro="http://ros.org/wiki/xacro" name="wheel">

  <!-- Wheel link -->


    <xacro:macro name="wheel" params="prefix">
  <link name="${prefix}_wheel_link">
    <visual>
      <geometry>
        <cylinder length="0.0206" radius="0.0352"/>
      </geometry>
 <material name="blue"/>
    </visual>
    <inertial>
      <mass value="10.0"/>
      <inertia ixx="1.0" ixy="0.0" ixz="0.0" iyy="1.0" iyz="0.0" izz="1.0"/>
    </inertial>
    <collision>
      <geometry>
        <cylinder length="0.0206" radius="0.0352"/>
      </geometry>
    </collision>
  </link>



  </xacro:macro>
    <xacro:macro name="wheel_color" params="prefix">

    <!-- Set the color of the wheels in Gazebo -->
  <gazebo reference="${prefix}_wheel_link">
    <material>Gazebo/Black</material>
  </gazebo>


 </xacro:macro>

    <xacro:macro  name="joint_wheel" params="prefix x">
  <!-- Joint between base link and wheel -->
  <joint name="${prefix}_wheel_joint" type="continuous">
    <parent link="base_link"/>
    <child link="${prefix}_wheel_link"/>
    <origin xyz="${x} 0 -0.09" rpy="0 1.57 0" />
        <axis rpy="0 0 0" xyz="0 0 1"/>
    <limit effort="10000" velocity="1000"/>
    <joint_properties damping="1.0" friction="1.0"/>
  </joint>
    </xacro:macro >
</robot>
